<?xml version="1.0" encoding="utf-8"?>
<!-- This URDF was automatically created by SolidWorks to URDF Exporter! Originally created by Stephen Brawner (brawner@gmail.com) 
     Commit Version: 1.5.1-0-g916b5db  Build Version: 1.5.7152.31018
     For more information, please see http://wiki.ros.org/sw_urdf_exporter -->
<robot
  name="FR5_V6">
  <link
    name="FR5_base_link">
    <inertial>
      <origin
        xyz="0.00031896 0.00029673 0.042463"
        rpy="0 0 0" />
      <mass
        value="1.6185" />
      <inertia
        ixx="0.0030836"
        ixy="1.5354E-05"
        ixz="1.9315E-05"
        iyy="0.0030825"
        iyz="1.7918E-05"
        izz="0.0045209" />
    </inertial>
    <visual>
      <origin
        xyz="0 0 0"
        rpy="0 0 0" />
      <geometry>
        <mesh
          filename="package://FR5_V6/meshes/FR5_base_link.STL" />
      </geometry>
      <material
        name="">
        <color
          rgba="1 1 1 1" />
      </material>
    </visual>
    <collision>
      <origin
        xyz="0 0 0"
        rpy="0 0 0" />
      <geometry>
        <mesh
          filename="package://FR5_V6/meshes/FR5_base_link.STL" />
      </geometry>
    </collision>
  </link>
  <link
    name="FR5_link1">
    <inertial>
      <origin
        xyz="-0.00019 -0.00226 -0.01828"
        rpy="0 0 0" />
      <mass
        value="4.64" />
      <inertia
        ixx="0.0093839"
        ixy="3.305E-05"
        ixz="-5.883E-05"
        iyy="0.0093245"
        iyz="-0.00022287"
        izz="0.0077422" />
    </inertial>
    <visual>
      <origin
        xyz="0 0 0"
        rpy="0 0 0" />
      <geometry>
        <mesh
          filename="package://FR5_V6/meshes/FR5_link1.STL" />
      </geometry>
      <material
        name="">
        <color
          rgba="1 1 1 1" />
      </material>
    </visual>
    <collision>
      <origin
        xyz="0 0 0"
        rpy="0 0 0" />
      <geometry>
        <mesh
          filename="package://FR5_V6/meshes/FR5_link1.STL" />
      </geometry>
    </collision>
  </link>
  <joint
    name="shoulder_pan_joint"
    type="revolute">
    <origin
      xyz="0 0 0.152"
      rpy="0 0 0" />
    <parent
      link="FR5_base_link" />
    <child
      link="FR5_link1" />
    <axis
      xyz="0 0 1" />
    <limit
      lower="-3.1415"
      upper="3.1415"
      effort="0"
      velocity="2.1" />
  </joint>
  <link
    name="FR5_link2">
    <inertial>
      <origin
        xyz="-0.2125 0 0.1212"
        rpy="0 0 0" />
      <mass
        value="10.08" />
      <inertia
        ixx="0.020605"
        ixy="0.00028019"
        ixz="2.62E-06"
        iyy="0.43899"
        iyz="-2.68E-06"
        izz="0.43546" />
    </inertial>
    <visual>
      <origin
        xyz="0 0 0"
        rpy="0 0 0" />
      <geometry>
        <mesh
          filename="package://FR5_V6/meshes/FR5_link2.STL" />
      </geometry>
      <material
        name="">
        <color
          rgba="1 1 1 1" />
      </material>
    </visual>
    <collision>
      <origin
        xyz="0 0 0"
        rpy="0 0 0" />
      <geometry>
        <mesh
          filename="package://FR5_V6/meshes/FR5_link2.STL" />
      </geometry>
    </collision>
  </link>
  <joint
    name="shoulder_lift_joint"
    type="revolute">
    <origin
      xyz="0 0 0"
      rpy="1.5708 0 0" />
    <parent
      link="FR5_link1" />
    <child
      link="FR5_link2" />
    <axis
      xyz="0 0 1" />
    <limit
      lower="-4.712"
      upper="1.57"
      effort="0"
      velocity="2.1" />
  </joint>
  <link
    name="FR5_link3">
    <inertial>
      <origin
        xyz="-0.27238 0.00017 0.01259"
        rpy="0 0 0" />
      <mass
        value="2.71" />
      <inertia
        ixx="0.0035754"
        ixy="9.57E-05"
        ixz="0.00022485"
        iyy="0.071483"
        iyz="3.43E-06"
        izz="0.071119" />
    </inertial>
    <visual>
      <origin
        xyz="0 0 0"
        rpy="0 0 0" />
      <geometry>
        <mesh
          filename="package://FR5_V6/meshes/FR5_link3.STL" />
      </geometry>
      <material
        name="">
        <color
          rgba="1 1 1 1" />
      </material>
    </visual>
    <collision>
      <origin
        xyz="0 0 0"
        rpy="0 0 0" />
      <geometry>
        <mesh
          filename="package://FR5_V6/meshes/FR5_link3.STL" />
      </geometry>
    </collision>
  </link>
  <joint
    name="elbow_joint"
    type="revolute">
    <origin
      xyz="-0.425 0 0"
      rpy="0 0 0" />
    <parent
      link="FR5_link2" />
    <child
      link="FR5_link3" />
    <axis
      xyz="0 0 1" />
    <limit
      lower="-3.1415"
      upper="3.1415"
      effort="0"
      velocity="3.14" />
  </joint>
  <link
    name="FR5_link4">
    <inertial>
      <origin
        xyz="5E-05 -0.01468 -0.00233"
        rpy="0 0 0" />
      <mass
        value="1.56" />
      <inertia
        ixx="0.001626"
        ixy="3.47E-06"
        ixz="-2.85E-06"
        iyy="0.0012553"
        iyz="-6.131E-05"
        izz="0.0015802" />
    </inertial>
    <visual>
      <origin
        xyz="0 0 0"
        rpy="0 0 0" />
      <geometry>
        <mesh
          filename="package://FR5_V6/meshes/FR5_link4.STL" />
      </geometry>
      <material
        name="">
        <color
          rgba="1 1 1 1" />
      </material>
    </visual>
    <collision>
      <origin
        xyz="0 0 0"
        rpy="0 0 0" />
      <geometry>
        <mesh
          filename="package://FR5_V6/meshes/FR5_link4.STL" />
      </geometry>
    </collision>
  </link>
  <joint
    name="wrist_1_joint"
    type="revolute">
    <origin
      xyz="-0.395 0 0.102"
      rpy="0 0 0" />
    <parent
      link="FR5_link3" />
    <child
      link="FR5_link4" />
    <axis
      xyz="0 0 1" />
    <limit
      lower="-4.712"
      upper="1.57"
      effort="0"
      velocity="2.1" />
  </joint>
  <link
    name="FR5_link5">
    <inertial>
      <origin
        xyz="-5E-05 0.01468 -0.00233"
        rpy="0 0 0" />
      <mass
        value="1.56" />
      <inertia
        ixx="0.001626"
        ixy="3.47E-06"
        ixz="2.85E-06"
        iyy="0.0012553"
        iyz="6.131E-05"
        izz="0.0015802" />
    </inertial>
    <visual>
      <origin
        xyz="0 0 0"
        rpy="0 0 0" />
      <geometry>
        <mesh
          filename="package://FR5_V6/meshes/FR5_link5.STL" />
      </geometry>
      <material
        name="">
        <color
          rgba="1 1 1 1" />
      </material>
    </visual>
    <collision>
      <origin
        xyz="0 0 0"
        rpy="0 0 0" />
      <geometry>
        <mesh
          filename="package://FR5_V6/meshes/FR5_link5.STL" />
      </geometry>
    </collision>
  </link>
  <joint
    name="wrist_2_joint"
    type="revolute">
    <origin
      xyz="0 -0.102 0"
      rpy="1.5708 0 0" />
    <parent
      link="FR5_link4" />
    <child
      link="FR5_link5" />
    <axis
      xyz="0 0 1" />
    <limit
      lower="-3.1415"
      upper="3.1415"
      effort="0"
      velocity="2.1" />
  </joint>
  <link
    name="FR5_link6">
    <inertial>
      <origin
        xyz="0.00093 0.00081 -0.02005"
        rpy="0 0 0" />
      <mass
        value="0.36" />
      <inertia
        ixx="0.00023009"
        ixy="1.3E-07"
        ixz="9.8E-07"
        iyy="0.00023049"
        iyz="8.5E-07"
        izz="0.0003593" />
    </inertial>
    <visual>
      <origin
        xyz="0 0 0"
        rpy="0 0 0" />
      <geometry>
        <mesh
          filename="package://FR5_V6/meshes/FR5_link6.STL" />
      </geometry>
      <material
        name="">
        <color
          rgba="1 1 1 1" />
      </material>
    </visual>
    <collision>
      <origin
        xyz="0 0 0"
        rpy="0 0 0" />
      <geometry>
        <mesh
          filename="package://FR5_V6/meshes/FR5_link6.STL" />
      </geometry>
    </collision>
  </link>
  <joint
    name="wrist_3_joint"
    type="revolute">
    <origin
      xyz="0 0.1 0"
      rpy="-1.5708 0 0" />
    <parent
      link="FR5_link5" />
    <child
      link="FR5_link6" />
    <axis
      xyz="0 0 1" />
    <limit
      lower="-3.1415"
      upper="3.1415"
      effort="0"
      velocity="2.1" />
  </joint>
</robot>